{
    DataVersion: 3700,
    size: [5, 5, 5],
    data: [
        {pos: [0, 0, 0], state: "pneumaticcraft:pressure_chamber_wall{wall_state:xmin_ymin_zmin}", nbt: {id: "pneumaticcraft:pressure_chamber_wall", valvePos: {X: 6, Y: 147, Z: 6}}},
        {pos: [0, 0, 1], state: "pneumaticcraft:pressure_chamber_wall{wall_state:xedge}", nbt: {id: "pneumaticcraft:pressure_chamber_wall", valvePos: {X: 6, Y: 147, Z: 6}}},
        {pos: [0, 0, 2], state: "pneumaticcraft:pressure_chamber_wall{wall_state:xedge}", nbt: {id: "pneumaticcraft:pressure_chamber_wall", valvePos: {X: 6, Y: 147, Z: 6}}},
        {pos: [0, 0, 3], state: "pneumaticcraft:pressure_chamber_wall{wall_state:xedge}", nbt: {id: "pneumaticcraft:pressure_chamber_wall", valvePos: {X: 6, Y: 147, Z: 6}}},
        {pos: [0, 0, 4], state: "pneumaticcraft:pressure_chamber_wall{wall_state:xmin_ymin_zmax}", nbt: {id: "pneumaticcraft:pressure_chamber_wall", valvePos: {X: 6, Y: 147, Z: 6}}},
        {pos: [1, 0, 0], state: "pneumaticcraft:pressure_chamber_wall{wall_state:zedge}", nbt: {id: "pneumaticcraft:pressure_chamber_wall", valvePos: {X: 6, Y: 147, Z: 6}}},
        {pos: [1, 0, 1], state: "pneumaticcraft:pressure_chamber_wall{wall_state:center}", nbt: {id: "pneumaticcraft:pressure_chamber_wall", valvePos: {X: 6, Y: 147, Z: 6}}},
        {pos: [1, 0, 2], state: "pneumaticcraft:pressure_chamber_wall{wall_state:center}", nbt: {id: "pneumaticcraft:pressure_chamber_wall", valvePos: {X: 6, Y: 147, Z: 6}}},
        {pos: [1, 0, 3], state: "pneumaticcraft:pressure_chamber_wall{wall_state:center}", nbt: {id: "pneumaticcraft:pressure_chamber_wall", valvePos: {X: 6, Y: 147, Z: 6}}},
        {pos: [1, 0, 4], state: "pneumaticcraft:pressure_chamber_wall{wall_state:zedge}", nbt: {id: "pneumaticcraft:pressure_chamber_wall", valvePos: {X: 6, Y: 147, Z: 6}}},
        {pos: [2, 0, 0], state: "pneumaticcraft:pressure_chamber_wall{wall_state:zedge}", nbt: {id: "pneumaticcraft:pressure_chamber_wall", valvePos: {X: 6, Y: 147, Z: 6}}},
        {pos: [2, 0, 1], state: "pneumaticcraft:pressure_chamber_wall{wall_state:center}", nbt: {id: "pneumaticcraft:pressure_chamber_wall", valvePos: {X: 6, Y: 147, Z: 6}}},
        {pos: [2, 0, 2], state: "pneumaticcraft:pressure_chamber_wall{wall_state:center}", nbt: {id: "pneumaticcraft:pressure_chamber_wall", valvePos: {X: 6, Y: 147, Z: 6}}},
        {pos: [2, 0, 3], state: "pneumaticcraft:pressure_chamber_wall{wall_state:center}", nbt: {id: "pneumaticcraft:pressure_chamber_wall", valvePos: {X: 6, Y: 147, Z: 6}}},
        {pos: [2, 0, 4], state: "pneumaticcraft:pressure_chamber_wall{wall_state:zedge}", nbt: {id: "pneumaticcraft:pressure_chamber_wall", valvePos: {X: 6, Y: 147, Z: 6}}},
        {pos: [3, 0, 0], state: "pneumaticcraft:pressure_chamber_wall{wall_state:zedge}", nbt: {id: "pneumaticcraft:pressure_chamber_wall", valvePos: {X: 6, Y: 147, Z: 6}}},
        {pos: [3, 0, 1], state: "pneumaticcraft:pressure_chamber_wall{wall_state:center}", nbt: {id: "pneumaticcraft:pressure_chamber_wall", valvePos: {X: 6, Y: 147, Z: 6}}},
        {pos: [3, 0, 2], state: "pneumaticcraft:pressure_chamber_wall{wall_state:center}", nbt: {id: "pneumaticcraft:pressure_chamber_wall", valvePos: {X: 6, Y: 147, Z: 6}}},
        {pos: [3, 0, 3], state: "pneumaticcraft:pressure_chamber_wall{wall_state:center}", nbt: {id: "pneumaticcraft:pressure_chamber_wall", valvePos: {X: 6, Y: 147, Z: 6}}},
        {pos: [3, 0, 4], state: "pneumaticcraft:pressure_chamber_wall{wall_state:zedge}", nbt: {id: "pneumaticcraft:pressure_chamber_wall", valvePos: {X: 6, Y: 147, Z: 6}}},
        {pos: [4, 0, 0], state: "pneumaticcraft:pressure_chamber_wall{wall_state:xmin_ymax_zmax}", nbt: {id: "pneumaticcraft:pressure_chamber_wall", valvePos: {X: 6, Y: 147, Z: 6}}},
        {pos: [4, 0, 1], state: "pneumaticcraft:pressure_chamber_wall{wall_state:xedge}", nbt: {id: "pneumaticcraft:pressure_chamber_wall", valvePos: {X: 6, Y: 147, Z: 6}}},
        {pos: [4, 0, 2], state: "pneumaticcraft:pressure_chamber_wall{wall_state:xedge}", nbt: {id: "pneumaticcraft:pressure_chamber_wall", valvePos: {X: 6, Y: 147, Z: 6}}},
        {pos: [4, 0, 3], state: "pneumaticcraft:pressure_chamber_wall{wall_state:xedge}", nbt: {id: "pneumaticcraft:pressure_chamber_wall", valvePos: {X: 6, Y: 147, Z: 6}}},
        {pos: [4, 0, 4], state: "pneumaticcraft:pressure_chamber_wall{wall_state:xmin_ymax_zmin}", nbt: {id: "pneumaticcraft:pressure_chamber_wall", valvePos: {X: 6, Y: 147, Z: 6}}},
        {pos: [0, 1, 0], state: "pneumaticcraft:pressure_chamber_wall{wall_state:yedge}", nbt: {id: "pneumaticcraft:pressure_chamber_wall", valvePos: {X: 6, Y: 147, Z: 6}}},
        {pos: [0, 1, 1], state: "pneumaticcraft:pressure_chamber_interface{facing:east}", nbt: {Items: {Items: [], Size: 1}, UpgradeInventory: {Items: [], Size: 4}, exportAny: 0b, id: "pneumaticcraft:pressure_chamber_interface", inputProgress: 40.0f, interfaceMode: 1, outputProgress: 0.0f, valvePos: {X: 6, Y: 147, Z: 6}}},
        {pos: [0, 1, 2], state: "pneumaticcraft:pressure_chamber_glass{formed:true}", nbt: {id: "pneumaticcraft:pressure_chamber_wall", valvePos: {X: 6, Y: 147, Z: 6}}},
        {pos: [0, 1, 3], state: "pneumaticcraft:pressure_chamber_interface{facing:west}", nbt: {Items: {Items: [], Size: 1}, UpgradeInventory: {Items: [], Size: 4}, exportAny: 0b, id: "pneumaticcraft:pressure_chamber_interface", inputProgress: 40.0f, interfaceMode: 2, outputProgress: 0.0f, valvePos: {X: 6, Y: 147, Z: 6}}},
        {pos: [0, 1, 4], state: "pneumaticcraft:pressure_chamber_wall{wall_state:yedge}", nbt: {id: "pneumaticcraft:pressure_chamber_wall", valvePos: {X: 6, Y: 147, Z: 6}}},
        {pos: [1, 1, 0], state: "pneumaticcraft:pressure_chamber_glass{formed:true}", nbt: {id: "pneumaticcraft:pressure_chamber_wall", valvePos: {X: 6, Y: 147, Z: 6}}},
        {pos: [1, 1, 4], state: "pneumaticcraft:pressure_chamber_valve{facing:north,formed:true}", nbt: {AirHandler: {Air: 0, Leaking: 2b}, UpgradeInventory: {Items: [], Size: 4}, Valves: [{X: 6, Y: 147, Z: 6}], craftedItems: {Items: [], Size: 9}, id: "pneumaticcraft:pressure_chamber_valve", itemsInChamber: {Items: [], Size: 18}, multiBlockSize: 5, multiBlockX: 5, multiBlockY: 146, multiBlockZ: 2}},
        {pos: [2, 1, 0], state: "pneumaticcraft:pressure_chamber_glass{formed:true}", nbt: {id: "pneumaticcraft:pressure_chamber_wall", valvePos: {X: 6, Y: 147, Z: 6}}},
        {pos: [2, 1, 4], state: "pneumaticcraft:pressure_chamber_glass{formed:true}", nbt: {id: "pneumaticcraft:pressure_chamber_wall", valvePos: {X: 6, Y: 147, Z: 6}}},
        {pos: [3, 1, 0], state: "pneumaticcraft:pressure_chamber_glass{formed:true}", nbt: {id: "pneumaticcraft:pressure_chamber_wall", valvePos: {X: 6, Y: 147, Z: 6}}},
        {pos: [3, 1, 4], state: "pneumaticcraft:pressure_chamber_glass{formed:true}", nbt: {id: "pneumaticcraft:pressure_chamber_wall", valvePos: {X: 6, Y: 147, Z: 6}}},
        {pos: [4, 1, 0], state: "pneumaticcraft:pressure_chamber_wall{wall_state:yedge}", nbt: {id: "pneumaticcraft:pressure_chamber_wall", valvePos: {X: 6, Y: 147, Z: 6}}},
        {pos: [4, 1, 1], state: "pneumaticcraft:pressure_chamber_glass{formed:true}", nbt: {id: "pneumaticcraft:pressure_chamber_wall", valvePos: {X: 6, Y: 147, Z: 6}}},
        {pos: [4, 1, 2], state: "pneumaticcraft:pressure_chamber_glass{formed:true}", nbt: {id: "pneumaticcraft:pressure_chamber_wall", valvePos: {X: 6, Y: 147, Z: 6}}},
        {pos: [4, 1, 3], state: "pneumaticcraft:pressure_chamber_glass{formed:true}", nbt: {id: "pneumaticcraft:pressure_chamber_wall", valvePos: {X: 6, Y: 147, Z: 6}}},
        {pos: [4, 1, 4], state: "pneumaticcraft:pressure_chamber_wall{wall_state:yedge}", nbt: {id: "pneumaticcraft:pressure_chamber_wall", valvePos: {X: 6, Y: 147, Z: 6}}},
        {pos: [0, 2, 0], state: "pneumaticcraft:pressure_chamber_wall{wall_state:yedge}", nbt: {id: "pneumaticcraft:pressure_chamber_wall", valvePos: {X: 6, Y: 147, Z: 6}}},
        {pos: [0, 2, 1], state: "pneumaticcraft:pressure_chamber_glass{formed:true}", nbt: {id: "pneumaticcraft:pressure_chamber_wall", valvePos: {X: 6, Y: 147, Z: 6}}},
        {pos: [0, 2, 2], state: "pneumaticcraft:pressure_chamber_glass{formed:true}", nbt: {id: "pneumaticcraft:pressure_chamber_wall", valvePos: {X: 6, Y: 147, Z: 6}}},
        {pos: [0, 2, 3], state: "pneumaticcraft:pressure_chamber_glass{formed:true}", nbt: {id: "pneumaticcraft:pressure_chamber_wall", valvePos: {X: 6, Y: 147, Z: 6}}},
        {pos: [0, 2, 4], state: "pneumaticcraft:pressure_chamber_wall{wall_state:yedge}", nbt: {id: "pneumaticcraft:pressure_chamber_wall", valvePos: {X: 6, Y: 147, Z: 6}}},
        {pos: [1, 2, 0], state: "pneumaticcraft:pressure_chamber_glass{formed:true}", nbt: {id: "pneumaticcraft:pressure_chamber_wall", valvePos: {X: 6, Y: 147, Z: 6}}},
        {pos: [1, 2, 4], state: "pneumaticcraft:pressure_chamber_glass{formed:true}", nbt: {id: "pneumaticcraft:pressure_chamber_wall", valvePos: {X: 6, Y: 147, Z: 6}}},
        {pos: [2, 2, 0], state: "pneumaticcraft:pressure_chamber_glass{formed:true}", nbt: {id: "pneumaticcraft:pressure_chamber_wall", valvePos: {X: 6, Y: 147, Z: 6}}},
        {pos: [2, 2, 4], state: "pneumaticcraft:pressure_chamber_glass{formed:true}", nbt: {id: "pneumaticcraft:pressure_chamber_wall", valvePos: {X: 6, Y: 147, Z: 6}}},
        {pos: [3, 2, 0], state: "pneumaticcraft:pressure_chamber_glass{formed:true}", nbt: {id: "pneumaticcraft:pressure_chamber_wall", valvePos: {X: 6, Y: 147, Z: 6}}},
        {pos: [3, 2, 4], state: "pneumaticcraft:pressure_chamber_glass{formed:true}", nbt: {id: "pneumaticcraft:pressure_chamber_wall", valvePos: {X: 6, Y: 147, Z: 6}}},
        {pos: [4, 2, 0], state: "pneumaticcraft:pressure_chamber_wall{wall_state:yedge}", nbt: {id: "pneumaticcraft:pressure_chamber_wall", valvePos: {X: 6, Y: 147, Z: 6}}},
        {pos: [4, 2, 1], state: "pneumaticcraft:pressure_chamber_glass{formed:true}", nbt: {id: "pneumaticcraft:pressure_chamber_wall", valvePos: {X: 6, Y: 147, Z: 6}}},
        {pos: [4, 2, 2], state: "pneumaticcraft:pressure_chamber_glass{formed:true}", nbt: {id: "pneumaticcraft:pressure_chamber_wall", valvePos: {X: 6, Y: 147, Z: 6}}},
        {pos: [4, 2, 3], state: "pneumaticcraft:pressure_chamber_glass{formed:true}", nbt: {id: "pneumaticcraft:pressure_chamber_wall", valvePos: {X: 6, Y: 147, Z: 6}}},
        {pos: [4, 2, 4], state: "pneumaticcraft:pressure_chamber_wall{wall_state:yedge}", nbt: {id: "pneumaticcraft:pressure_chamber_wall", valvePos: {X: 6, Y: 147, Z: 6}}},
        {pos: [0, 3, 0], state: "pneumaticcraft:pressure_chamber_wall{wall_state:yedge}", nbt: {id: "pneumaticcraft:pressure_chamber_wall", valvePos: {X: 6, Y: 147, Z: 6}}},
        {pos: [0, 3, 1], state: "pneumaticcraft:pressure_chamber_glass{formed:true}", nbt: {id: "pneumaticcraft:pressure_chamber_wall", valvePos: {X: 6, Y: 147, Z: 6}}},
        {pos: [0, 3, 2], state: "pneumaticcraft:pressure_chamber_glass{formed:true}", nbt: {id: "pneumaticcraft:pressure_chamber_wall", valvePos: {X: 6, Y: 147, Z: 6}}},
        {pos: [0, 3, 3], state: "pneumaticcraft:pressure_chamber_glass{formed:true}", nbt: {id: "pneumaticcraft:pressure_chamber_wall", valvePos: {X: 6, Y: 147, Z: 6}}},
        {pos: [0, 3, 4], state: "pneumaticcraft:pressure_chamber_wall{wall_state:yedge}", nbt: {id: "pneumaticcraft:pressure_chamber_wall", valvePos: {X: 6, Y: 147, Z: 6}}},
        {pos: [1, 3, 0], state: "pneumaticcraft:pressure_chamber_glass{formed:true}", nbt: {id: "pneumaticcraft:pressure_chamber_wall", valvePos: {X: 6, Y: 147, Z: 6}}},
        {pos: [1, 3, 4], state: "pneumaticcraft:pressure_chamber_glass{formed:true}", nbt: {id: "pneumaticcraft:pressure_chamber_wall", valvePos: {X: 6, Y: 147, Z: 6}}},
        {pos: [2, 3, 0], state: "pneumaticcraft:pressure_chamber_glass{formed:true}", nbt: {id: "pneumaticcraft:pressure_chamber_wall", valvePos: {X: 6, Y: 147, Z: 6}}},
        {pos: [2, 3, 4], state: "pneumaticcraft:pressure_chamber_glass{formed:true}", nbt: {id: "pneumaticcraft:pressure_chamber_wall", valvePos: {X: 6, Y: 147, Z: 6}}},
        {pos: [3, 3, 0], state: "pneumaticcraft:pressure_chamber_glass{formed:true}", nbt: {id: "pneumaticcraft:pressure_chamber_wall", valvePos: {X: 6, Y: 147, Z: 6}}},
        {pos: [3, 3, 4], state: "pneumaticcraft:pressure_chamber_glass{formed:true}", nbt: {id: "pneumaticcraft:pressure_chamber_wall", valvePos: {X: 6, Y: 147, Z: 6}}},
        {pos: [4, 3, 0], state: "pneumaticcraft:pressure_chamber_wall{wall_state:yedge}", nbt: {id: "pneumaticcraft:pressure_chamber_wall", valvePos: {X: 6, Y: 147, Z: 6}}},
        {pos: [4, 3, 1], state: "pneumaticcraft:pressure_chamber_glass{formed:true}", nbt: {id: "pneumaticcraft:pressure_chamber_wall", valvePos: {X: 6, Y: 147, Z: 6}}},
        {pos: [4, 3, 2], state: "pneumaticcraft:pressure_chamber_glass{formed:true}", nbt: {id: "pneumaticcraft:pressure_chamber_wall", valvePos: {X: 6, Y: 147, Z: 6}}},
        {pos: [4, 3, 3], state: "pneumaticcraft:pressure_chamber_glass{formed:true}", nbt: {id: "pneumaticcraft:pressure_chamber_wall", valvePos: {X: 6, Y: 147, Z: 6}}},
        {pos: [4, 3, 4], state: "pneumaticcraft:pressure_chamber_wall{wall_state:yedge}", nbt: {id: "pneumaticcraft:pressure_chamber_wall", valvePos: {X: 6, Y: 147, Z: 6}}},
        {pos: [0, 4, 0], state: "pneumaticcraft:pressure_chamber_wall{wall_state:xmin_ymax_zmin}", nbt: {id: "pneumaticcraft:pressure_chamber_wall", valvePos: {X: 6, Y: 147, Z: 6}}},
        {pos: [0, 4, 1], state: "pneumaticcraft:pressure_chamber_wall{wall_state:xedge}", nbt: {id: "pneumaticcraft:pressure_chamber_wall", valvePos: {X: 6, Y: 147, Z: 6}}},
        {pos: [0, 4, 2], state: "pneumaticcraft:pressure_chamber_wall{wall_state:xedge}", nbt: {id: "pneumaticcraft:pressure_chamber_wall", valvePos: {X: 6, Y: 147, Z: 6}}},
        {pos: [0, 4, 3], state: "pneumaticcraft:pressure_chamber_wall{wall_state:xedge}", nbt: {id: "pneumaticcraft:pressure_chamber_wall", valvePos: {X: 6, Y: 147, Z: 6}}},
        {pos: [0, 4, 4], state: "pneumaticcraft:pressure_chamber_wall{wall_state:xmin_ymax_zmax}", nbt: {id: "pneumaticcraft:pressure_chamber_wall", valvePos: {X: 6, Y: 147, Z: 6}}},
        {pos: [1, 4, 0], state: "pneumaticcraft:pressure_chamber_wall{wall_state:zedge}", nbt: {id: "pneumaticcraft:pressure_chamber_wall", valvePos: {X: 6, Y: 147, Z: 6}}},
        {pos: [1, 4, 1], state: "pneumaticcraft:pressure_chamber_glass{formed:true}", nbt: {id: "pneumaticcraft:pressure_chamber_wall", valvePos: {X: 6, Y: 147, Z: 6}}},
        {pos: [1, 4, 2], state: "pneumaticcraft:pressure_chamber_glass{formed:true}", nbt: {id: "pneumaticcraft:pressure_chamber_wall", valvePos: {X: 6, Y: 147, Z: 6}}},
        {pos: [1, 4, 3], state: "pneumaticcraft:pressure_chamber_glass{formed:true}", nbt: {id: "pneumaticcraft:pressure_chamber_wall", valvePos: {X: 6, Y: 147, Z: 6}}},
        {pos: [1, 4, 4], state: "pneumaticcraft:pressure_chamber_wall{wall_state:zedge}", nbt: {id: "pneumaticcraft:pressure_chamber_wall", valvePos: {X: 6, Y: 147, Z: 6}}},
        {pos: [2, 4, 0], state: "pneumaticcraft:pressure_chamber_wall{wall_state:zedge}", nbt: {id: "pneumaticcraft:pressure_chamber_wall", valvePos: {X: 6, Y: 147, Z: 6}}},
        {pos: [2, 4, 1], state: "pneumaticcraft:pressure_chamber_glass{formed:true}", nbt: {id: "pneumaticcraft:pressure_chamber_wall", valvePos: {X: 6, Y: 147, Z: 6}}},
        {pos: [2, 4, 2], state: "pneumaticcraft:pressure_chamber_glass{formed:true}", nbt: {id: "pneumaticcraft:pressure_chamber_wall", valvePos: {X: 6, Y: 147, Z: 6}}},
        {pos: [2, 4, 3], state: "pneumaticcraft:pressure_chamber_glass{formed:true}", nbt: {id: "pneumaticcraft:pressure_chamber_wall", valvePos: {X: 6, Y: 147, Z: 6}}},
        {pos: [2, 4, 4], state: "pneumaticcraft:pressure_chamber_wall{wall_state:zedge}", nbt: {id: "pneumaticcraft:pressure_chamber_wall", valvePos: {X: 6, Y: 147, Z: 6}}},
        {pos: [3, 4, 0], state: "pneumaticcraft:pressure_chamber_wall{wall_state:zedge}", nbt: {id: "pneumaticcraft:pressure_chamber_wall", valvePos: {X: 6, Y: 147, Z: 6}}},
        {pos: [3, 4, 1], state: "pneumaticcraft:pressure_chamber_glass{formed:true}", nbt: {id: "pneumaticcraft:pressure_chamber_wall", valvePos: {X: 6, Y: 147, Z: 6}}},
        {pos: [3, 4, 2], state: "pneumaticcraft:pressure_chamber_glass{formed:true}", nbt: {id: "pneumaticcraft:pressure_chamber_wall", valvePos: {X: 6, Y: 147, Z: 6}}},
        {pos: [3, 4, 3], state: "pneumaticcraft:pressure_chamber_glass{formed:true}", nbt: {id: "pneumaticcraft:pressure_chamber_wall", valvePos: {X: 6, Y: 147, Z: 6}}},
        {pos: [3, 4, 4], state: "pneumaticcraft:pressure_chamber_wall{wall_state:zedge}", nbt: {id: "pneumaticcraft:pressure_chamber_wall", valvePos: {X: 6, Y: 147, Z: 6}}},
        {pos: [4, 4, 0], state: "pneumaticcraft:pressure_chamber_wall{wall_state:xmin_ymin_zmax}", nbt: {id: "pneumaticcraft:pressure_chamber_wall", valvePos: {X: 6, Y: 147, Z: 6}}},
        {pos: [4, 4, 1], state: "pneumaticcraft:pressure_chamber_wall{wall_state:xedge}", nbt: {id: "pneumaticcraft:pressure_chamber_wall", valvePos: {X: 6, Y: 147, Z: 6}}},
        {pos: [4, 4, 2], state: "pneumaticcraft:pressure_chamber_wall{wall_state:xedge}", nbt: {id: "pneumaticcraft:pressure_chamber_wall", valvePos: {X: 6, Y: 147, Z: 6}}},
        {pos: [4, 4, 3], state: "pneumaticcraft:pressure_chamber_wall{wall_state:xedge}", nbt: {id: "pneumaticcraft:pressure_chamber_wall", valvePos: {X: 6, Y: 147, Z: 6}}},
        {pos: [4, 4, 4], state: "pneumaticcraft:pressure_chamber_wall{wall_state:xmin_ymin_zmin}", nbt: {id: "pneumaticcraft:pressure_chamber_wall", valvePos: {X: 6, Y: 147, Z: 6}}}
    ],
    entities: [],
    palette: [
        "pneumaticcraft:pressure_chamber_wall{wall_state:xmin_ymin_zmin}",
        "pneumaticcraft:pressure_chamber_wall{wall_state:xedge}",
        "pneumaticcraft:pressure_chamber_wall{wall_state:xmin_ymin_zmax}",
        "pneumaticcraft:pressure_chamber_wall{wall_state:zedge}",
        "pneumaticcraft:pressure_chamber_wall{wall_state:center}",
        "pneumaticcraft:pressure_chamber_wall{wall_state:xmin_ymax_zmax}",
        "pneumaticcraft:pressure_chamber_wall{wall_state:xmin_ymax_zmin}",
        "pneumaticcraft:pressure_chamber_wall{wall_state:yedge}",
        "pneumaticcraft:pressure_chamber_interface{facing:east}",
        "pneumaticcraft:pressure_chamber_glass{formed:true}",
        "pneumaticcraft:pressure_chamber_interface{facing:west}",
        "pneumaticcraft:pressure_chamber_valve{facing:north,formed:true}"
    ]
}