{
    DataVersion: 3700,
    size: [3, 4, 3],
    data: [
        {pos: [0, 0, 0], state: "modern_industrialization:bronze_fluid_input_hatch", nbt: {extractFluids: 0b, extractItems: 0b, facingDirection: 4, fluids: [{amount: 0L, capacity: 4000L, key: {fluid: "minecraft:empty"}, machineLocked: 0b, pipesExtract: 0b, pipesInsert: 1b, playerExtract: 1b, playerInsert: 1b, playerLockable: 1b, playerLocked: 0b}], id: "modern_industrialization:bronze_fluid_input_hatch", items: [], outputDirection: 4, placer: "a2d74ce4-3e79-4f7e-a2c8-04efd45109d4"}},
        {pos: [0, 0, 1], state: "modern_industrialization:bronze_item_input_hatch", nbt: {extractFluids: 0b, extractItems: 0b, facingDirection: 4, fluids: [], id: "modern_industrialization:bronze_item_input_hatch", items: [{adjCap: 64, amount: 0L, key: {item: "minecraft:air"}, machineLocked: 0b, pipesExtract: 0b, pipesInsert: 1b, playerExtract: 1b, playerInsert: 1b, playerLockable: 1b, playerLocked: 0b}], outputDirection: 4, placer: "a2d74ce4-3e79-4f7e-a2c8-04efd45109d4"}},
        {pos: [0, 0, 2], state: "modern_industrialization:bronze_fluid_output_hatch", nbt: {extractFluids: 0b, extractItems: 0b, facingDirection: 4, fluids: [{amount: 0L, capacity: 4000L, key: {fluid: "minecraft:empty"}, machineLocked: 0b, pipesExtract: 1b, pipesInsert: 0b, playerExtract: 1b, playerInsert: 0b, playerLockable: 1b, playerLocked: 0b}], id: "modern_industrialization:bronze_fluid_output_hatch", items: [], outputDirection: 4, placer: "a2d74ce4-3e79-4f7e-a2c8-04efd45109d4"}},
        {pos: [1, 0, 0], state: "modern_industrialization:heatproof_machine_casing"},
        {pos: [1, 0, 1], state: "modern_industrialization:heatproof_machine_casing"},
        {pos: [1, 0, 2], state: "modern_industrialization:heatproof_machine_casing"},
        {pos: [2, 0, 0], state: "modern_industrialization:heatproof_machine_casing"},
        {pos: [2, 0, 1], state: "modern_industrialization:heatproof_machine_casing"},
        {pos: [2, 0, 2], state: "modern_industrialization:heatproof_machine_casing"},
        {pos: [0, 1, 0], state: "modern_industrialization:bronze_plated_bricks"},
        {pos: [0, 1, 1], state: "modern_industrialization:large_steam_boiler", nbt: {burningEuBuffer: 0L, facingDirection: 4, id: "modern_industrialization:large_steam_boiler", placer: "a2d74ce4-3e79-4f7e-a2c8-04efd45109d4", redstoneModuleStack: {Count: 7b, id: "minecraft:air"}, steamBuffer: {}, temperature: 0.0d}},
        {pos: [0, 1, 2], state: "modern_industrialization:bronze_plated_bricks"},
        {pos: [1, 1, 0], state: "modern_industrialization:bronze_plated_bricks"},
        {pos: [1, 1, 1], state: "modern_industrialization:bronze_machine_casing_pipe"},
        {pos: [1, 1, 2], state: "modern_industrialization:bronze_plated_bricks"},
        {pos: [2, 1, 0], state: "modern_industrialization:bronze_plated_bricks"},
        {pos: [2, 1, 1], state: "modern_industrialization:bronze_plated_bricks"},
        {pos: [2, 1, 2], state: "modern_industrialization:bronze_plated_bricks"},
        {pos: [0, 2, 0], state: "modern_industrialization:bronze_plated_bricks"},
        {pos: [0, 2, 1], state: "modern_industrialization:bronze_plated_bricks"},
        {pos: [0, 2, 2], state: "modern_industrialization:bronze_plated_bricks"},
        {pos: [1, 2, 0], state: "modern_industrialization:bronze_plated_bricks"},
        {pos: [1, 2, 1], state: "modern_industrialization:bronze_machine_casing_pipe"},
        {pos: [1, 2, 2], state: "modern_industrialization:bronze_plated_bricks"},
        {pos: [2, 2, 0], state: "modern_industrialization:bronze_plated_bricks"},
        {pos: [2, 2, 1], state: "modern_industrialization:bronze_plated_bricks"},
        {pos: [2, 2, 2], state: "modern_industrialization:bronze_plated_bricks"},
        {pos: [0, 3, 0], state: "modern_industrialization:bronze_plated_bricks"},
        {pos: [0, 3, 1], state: "modern_industrialization:bronze_plated_bricks"},
        {pos: [0, 3, 2], state: "modern_industrialization:bronze_plated_bricks"},
        {pos: [1, 3, 0], state: "modern_industrialization:bronze_plated_bricks"},
        {pos: [1, 3, 1], state: "modern_industrialization:bronze_plated_bricks"},
        {pos: [1, 3, 2], state: "modern_industrialization:bronze_plated_bricks"},
        {pos: [2, 3, 0], state: "modern_industrialization:bronze_plated_bricks"},
        {pos: [2, 3, 1], state: "modern_industrialization:bronze_plated_bricks"},
        {pos: [2, 3, 2], state: "modern_industrialization:bronze_plated_bricks"}
    ],
    entities: [],
    palette: [
        "modern_industrialization:heatproof_machine_casing",
        "modern_industrialization:bronze_plated_bricks",
        "modern_industrialization:bronze_machine_casing_pipe",
        "modern_industrialization:bronze_fluid_input_hatch",
        "modern_industrialization:bronze_item_input_hatch",
        "modern_industrialization:bronze_fluid_output_hatch",
        "modern_industrialization:large_steam_boiler"
    ]
}