{
    DataVersion: 3700,
    size: [5, 5, 5],
    data: [
        {pos: [0, 0, 0], state: "modern_industrialization:steel_machine_casing"},
        {pos: [0, 0, 1], state: "modern_industrialization:steel_machine_casing"},
        {pos: [0, 0, 2], state: "modern_industrialization:steel_machine_casing"},
        {pos: [0, 0, 3], state: "modern_industrialization:steel_machine_casing"},
        {pos: [0, 0, 4], state: "modern_industrialization:steel_machine_casing"},
        {pos: [1, 0, 0], state: "modern_industrialization:steel_machine_casing"},
        {pos: [1, 0, 1], state: "minecraft:glass"},
        {pos: [1, 0, 2], state: "minecraft:glass"},
        {pos: [1, 0, 3], state: "minecraft:glass"},
        {pos: [1, 0, 4], state: "modern_industrialization:steel_machine_casing"},
        {pos: [2, 0, 0], state: "modern_industrialization:steel_machine_casing"},
        {pos: [2, 0, 1], state: "minecraft:glass"},
        {pos: [2, 0, 2], state: "minecraft:glass"},
        {pos: [2, 0, 3], state: "minecraft:glass"},
        {pos: [2, 0, 4], state: "modern_industrialization:steel_machine_casing"},
        {pos: [3, 0, 0], state: "modern_industrialization:steel_machine_casing"},
        {pos: [3, 0, 1], state: "minecraft:glass"},
        {pos: [3, 0, 2], state: "minecraft:glass"},
        {pos: [3, 0, 3], state: "minecraft:glass"},
        {pos: [3, 0, 4], state: "modern_industrialization:steel_machine_casing"},
        {pos: [4, 0, 0], state: "modern_industrialization:steel_machine_casing"},
        {pos: [4, 0, 1], state: "modern_industrialization:steel_machine_casing"},
        {pos: [4, 0, 2], state: "modern_industrialization:steel_machine_casing"},
        {pos: [4, 0, 3], state: "modern_industrialization:steel_machine_casing"},
        {pos: [4, 0, 4], state: "modern_industrialization:steel_machine_casing"},
        {pos: [0, 1, 0], state: "modern_industrialization:steel_machine_casing"},
        {pos: [0, 1, 1], state: "modern_industrialization:large_tank_hatch", nbt: {facingDirection: 4, id: "modern_industrialization:large_tank_hatch", placer: "a2d74ce4-3e79-4f7e-a2c8-04efd45109d4"}},
        {pos: [0, 1, 2], state: "modern_industrialization:large_tank", nbt: {activeShape: 37, amount: 6611000L, capacity: 8000000L, facingDirection: 4, fluid: {fluid: "minecraft:water"}, id: "modern_industrialization:large_tank", placer: "a2d74ce4-3e79-4f7e-a2c8-04efd45109d4"}},
        {pos: [0, 1, 3], state: "minecraft:glass"},
        {pos: [0, 1, 4], state: "modern_industrialization:steel_machine_casing"},
        {pos: [1, 1, 0], state: "minecraft:glass"},
        {pos: [1, 1, 4], state: "minecraft:glass"},
        {pos: [2, 1, 0], state: "minecraft:glass"},
        {pos: [2, 1, 4], state: "minecraft:glass"},
        {pos: [3, 1, 0], state: "minecraft:glass"},
        {pos: [3, 1, 4], state: "minecraft:glass"},
        {pos: [4, 1, 0], state: "modern_industrialization:steel_machine_casing"},
        {pos: [4, 1, 1], state: "minecraft:glass"},
        {pos: [4, 1, 2], state: "minecraft:glass"},
        {pos: [4, 1, 3], state: "minecraft:glass"},
        {pos: [4, 1, 4], state: "modern_industrialization:steel_machine_casing"},
        {pos: [0, 2, 0], state: "modern_industrialization:steel_machine_casing"},
        {pos: [0, 2, 1], state: "minecraft:glass"},
        {pos: [0, 2, 2], state: "minecraft:glass"},
        {pos: [0, 2, 3], state: "minecraft:glass"},
        {pos: [0, 2, 4], state: "modern_industrialization:steel_machine_casing"},
        {pos: [1, 2, 0], state: "minecraft:glass"},
        {pos: [1, 2, 4], state: "minecraft:glass"},
        {pos: [2, 2, 0], state: "minecraft:glass"},
        {pos: [2, 2, 4], state: "minecraft:glass"},
        {pos: [3, 2, 0], state: "minecraft:glass"},
        {pos: [3, 2, 4], state: "minecraft:glass"},
        {pos: [4, 2, 0], state: "modern_industrialization:steel_machine_casing"},
        {pos: [4, 2, 1], state: "minecraft:glass"},
        {pos: [4, 2, 2], state: "minecraft:glass"},
        {pos: [4, 2, 3], state: "minecraft:glass"},
        {pos: [4, 2, 4], state: "modern_industrialization:steel_machine_casing"},
        {pos: [0, 3, 0], state: "modern_industrialization:steel_machine_casing"},
        {pos: [0, 3, 1], state: "minecraft:glass"},
        {pos: [0, 3, 2], state: "minecraft:glass"},
        {pos: [0, 3, 3], state: "minecraft:glass"},
        {pos: [0, 3, 4], state: "modern_industrialization:steel_machine_casing"},
        {pos: [1, 3, 0], state: "minecraft:glass"},
        {pos: [1, 3, 4], state: "minecraft:glass"},
        {pos: [2, 3, 0], state: "minecraft:glass"},
        {pos: [2, 3, 4], state: "minecraft:glass"},
        {pos: [3, 3, 0], state: "minecraft:glass"},
        {pos: [3, 3, 4], state: "minecraft:glass"},
        {pos: [4, 3, 0], state: "modern_industrialization:steel_machine_casing"},
        {pos: [4, 3, 1], state: "minecraft:glass"},
        {pos: [4, 3, 2], state: "minecraft:glass"},
        {pos: [4, 3, 3], state: "minecraft:glass"},
        {pos: [4, 3, 4], state: "modern_industrialization:steel_machine_casing"},
        {pos: [0, 4, 0], state: "modern_industrialization:steel_machine_casing"},
        {pos: [0, 4, 1], state: "modern_industrialization:steel_machine_casing"},
        {pos: [0, 4, 2], state: "modern_industrialization:steel_machine_casing"},
        {pos: [0, 4, 3], state: "modern_industrialization:steel_machine_casing"},
        {pos: [0, 4, 4], state: "modern_industrialization:steel_machine_casing"},
        {pos: [1, 4, 0], state: "modern_industrialization:steel_machine_casing"},
        {pos: [1, 4, 1], state: "minecraft:glass"},
        {pos: [1, 4, 2], state: "minecraft:glass"},
        {pos: [1, 4, 3], state: "minecraft:glass"},
        {pos: [1, 4, 4], state: "modern_industrialization:steel_machine_casing"},
        {pos: [2, 4, 0], state: "modern_industrialization:steel_machine_casing"},
        {pos: [2, 4, 1], state: "minecraft:glass"},
        {pos: [2, 4, 2], state: "minecraft:glass"},
        {pos: [2, 4, 3], state: "minecraft:glass"},
        {pos: [2, 4, 4], state: "modern_industrialization:steel_machine_casing"},
        {pos: [3, 4, 0], state: "modern_industrialization:steel_machine_casing"},
        {pos: [3, 4, 1], state: "minecraft:glass"},
        {pos: [3, 4, 2], state: "minecraft:glass"},
        {pos: [3, 4, 3], state: "minecraft:glass"},
        {pos: [3, 4, 4], state: "modern_industrialization:steel_machine_casing"},
        {pos: [4, 4, 0], state: "modern_industrialization:steel_machine_casing"},
        {pos: [4, 4, 1], state: "modern_industrialization:steel_machine_casing"},
        {pos: [4, 4, 2], state: "modern_industrialization:steel_machine_casing"},
        {pos: [4, 4, 3], state: "modern_industrialization:steel_machine_casing"},
        {pos: [4, 4, 4], state: "modern_industrialization:steel_machine_casing"}
    ],
    entities: [],
    palette: [
        "modern_industrialization:steel_machine_casing",
        "minecraft:glass",
        "modern_industrialization:large_tank_hatch",
        "modern_industrialization:large_tank"
    ]
}